Workbook

Sheet README
A1: MPG Cost Estimating Relationship (CER): the math behind the deck, live
A3: Purpose: every statistic quoted in the MPG Prediction Deck is recomputed here as an Excel formula over the actual data, so the
A4: coefficients, R-squared, F, t, p, nested F-tests, elasticities, and the 50-year normalization can be inspected and recalculated on demand.
A6: Sheets
A7: Data: the 1,285 Model Year 2024 model types in the final CER (775 gasoline/diesel, 250 hybrid, 260 battery-electric) with log and dummy columns.
A8: Data_Combustion: the 1,025 combustion-only rows used by the original (combustion-only) CER, alternative A.
A9: CER: the final equation ln(MPG) = b0 + b1 ln(weight) + b2 ln(HP) + b3 hybrid + b4 electric, fit with LINEST; t, p, VIF, elasticities, prediction band, outliers.
A10: Alternatives: specifications A through E, each fit with LINEST, and the nested F-tests that decided between them.
A11: Normalization: the 50-year fleet series re-expressed at 2024 weight and horsepower using the CER's own elasticities, trend fit, and 2045 projection.
A12: Class Productivity: figs 43, 45, 46: class series 1975 to 2024, in-class BEV share, live BEV backing-out, both normalizations, LINEST trends, R-squared, 2045 projections.
A13: EV Productivity: fig 44: the Tesla fleet series (also the BEV proxy), normalized to constant weight, trend and R-squared.
A14: Diffusion: the technology S-curves behind slide 7: share data for five technologies, the logistic parameters, live fitted curves, R-squared, 10-to-90% years, projections, and an Excel cross-check of k and t0.
... A26: DATA_SOURCES.md, github.com/SCherwonik/OS3180.

Sheet Data
A1: carline | B1: manufacturer | C1: powertrain | D1: MPG or MPGe (unadjusted 2-cycle) | E1: weight_lbs | F1: horsepower | G1: footprint_sqft | H1: hp_source | I1: ln_mpg | J1: ln_weight | K1: ln_hp | L1: hybrid | M1: bev | N1: footprint (spec B block) | O1: electrified | P1: ordinal_0_1_2 | Q1: C: ln_weight | R1: C: ln_hp | S1: C: footprint | T1: C: electrified | U1: D: ln_weight | V1: D: ln_hp | W1: D: footprint | X1: D: ordinal | Y1: E: ln_weight | Z1: E: ln_hp | AA1: E: footprint | AB1: E: hybrid | AC1: E: bev | AD1: E: bev x ln_weight | AE1: E: bev x ln_hp | AF1: E: bev x footprint | AG1: VIF ln_hp: ln_weight | AH1: VIF ln_hp: hybrid | AI1: VIF ln_hp: bev | AJ1: VIF hybrid: ln_weight | AK1: VIF hybrid: ln_hp | AL1: VIF hybrid: bev | AM1: pred ln_mpg (CER) | AN1: pred MPG (CER) | AO1: residual (CER) | AP1: pred ln_mpg (spec C) | AQ1: residual (spec C)
A2: DB12 V8 | B2: Aston Martin Lagonda | C2: gas_diesel | D2: 22.4729 | E2: 4500 | F2: 680 | G2: 50 | H2: FE file ENG_RATED_HP | I2: =LN(D2) -> 3.1123101 | J2: =LN(E2) -> 8.4118327 | K2: =LN(F2) -> 6.5220928 | L2: 0 | M2: 0 | N2: =G2 -> 50 | O2: =L2+M2 -> 0 | P2: =L2+2*M2 -> 0 | Q2: =J2 -> 8.4118327 | R2: =K2 -> 6.5220928 | S2: =G2 -> 50 | T2: =O2 -> 0 | U2: =J2 -> 8.4118327 | V2: =K2 -> 6.5220928 | W2: =G2 -> 50 | X2: =P2 -> 0 | Y2: =J2 -> 8.4118327 | Z2: =K2 -> 6.5220928 | AA2: =G2 -> 50 | AB2: =L2 -> 0 | AC2: =M2 -> 0 | AD2: =M2*J2 -> 0 | AE2: =M2*K2 -> 0 | AF2: =M2*G2 -> 0 | AG2: =J2 -> 8.4118327 | AH2: =L2 -> 0 | AI2: =M2 -> 0 | AJ2: =J2 -> 8.4118327 | AK2: =K2 -> 6.5220928 | AL2: =M2 -> 0 | AM2: =CER!$C$7+CER!$C$8*J2+CER!$C$9*K2+CER!$C$10*L2+CER!$C$11*M2 -> 3.0433906 | AN2: =EXP(AM2) -> 20.976245 | AO2: =I2-AM2 -> 0.068919534 | AP2: =Alternatives!$F$25+Alternatives!$F$26*J2+Alternatives!$F$27*K2+Alternatives!$F$28*G2+Alternatives!$F$29*O2 -> 3.1715446 | AQ2: =I2-AP2 -> -0.059234477
A3: Valour | B3: Aston Martin Lagonda | C3: gas_diesel | D3: 18.3624 | E3: 4000 | F3: 715 | G3: 48.2 | H3: FE file ENG_RATED_HP | I3: =LN(D3) -> 2.9103051 | J3: =LN(E3) -> 8.2940496 | K3: =LN(F3) -> 6.5722825 | L3: 0 | M3: 0 | N3: =G3 -> 48.2 | O3: =L3+M3 -> 0 | P3: =L3+2*M3 -> 0 | Q3: =J3 -> 8.2940496 | R3: =K3 -> 6.5722825 | S3: =G3 -> 48.2 | T3: =O3 -> 0 | U3: =J3 -> 8.2940496 | V3: =K3 -> 6.5722825 | W3: =G3 -> 48.2 | X3: =P3 -> 0 | Y3: =J3 -> 8.2940496 | Z3: =K3 -> 6.5722825 | AA3: =G3 -> 48.2 | AB3: =L3 -> 0 | AC3: =M3 -> 0 | AD3: =M3*J3 -> 0 | AE3: =M3*K3 -> 0 | AF3: =M3*G3 -> 0 | AG3: =J3 -> 8.2940496 | AH3: =L3 -> 0 | AI3: =M3 -> 0 | AJ3: =J3 -> 8.2940496 | AK3: =K3 -> 6.5722825 | AL3: =M3 -> 0 | AM3: =CER!$C$7+CER!$C$8*J3+CER!$C$9*K3+CER!$C$10*L3+CER!$C$11*M3 -> 3.0781949 | AN3: =EXP(AM3) -> 21.719161 | AO3: =I3-AM3 -> -0.16788977 | AP3: =Alternatives!$F$25+Alternatives!$F$26*J3+Alternatives!$F$27*K3+Alternatives!$F$28*G3+Alternatives!$F$29*O3 -> 3.1380119 | AQ3: =I3-AP3 -> -0.22770684
A4: DBX V8 | B4: Aston Martin Lagonda | C4: gas_diesel | D4: 20.6665 | E4: 5500 | F4: 550 | G4: 55.4 | H4: FE file ENG_RATED_HP | I4: =LN(D4) -> 3.028514 | J4: =LN(E4) -> 8.6125034 | K4: =LN(F4) -> 6.3099183 | L4: 0 | M4: 0 | N4: =G4 -> 55.4 | O4: =L4+M4 -> 0 | P4: =L4+2*M4 -> 0 | Q4: =J4 -> 8.6125034 | R4: =K4 -> 6.3099183 | S4: =G4 -> 55.4 | T4: =O4 -> 0 | U4: =J4 -> 8.6125034 | V4: =K4 -> 6.3099183 | W4: =G4 -> 55.4 | X4: =P4 -> 0 | Y4: =J4 -> 8.6125034 | Z4: =K4 -> 6.3099183 | AA4: =G4 -> 55.4 | AB4: =L4 -> 0 | AC4: =M4 -> 0 | AD4: =M4*J4 -> 0 | AE4: =M4*K4 -> 0 | AF4: =M4*G4 -> 0 | AG4: =J4 -> 8.6125034 | AH4: =L4 -> 0 | AI4: =M4 -> 0 | AJ4: =J4 -> 8.6125034 | AK4: =K4 -> 6.3099183 | AL4: =M4 -> 0 | AM4: =CER!$C$7+CER!$C$8*J4+CER!$C$9*K4+CER!$C$10*L4+CER!$C$11*M4 -> 3.0308256 | AN4: =EXP(AM4) -> 20.714327 | AO4: =I4-AM4 -> -0.0023115748 | AP4: =Alternatives!$F$25+Alternatives!$F$26*J4+Alternatives!$F$27*K4+Alternatives!$F$28*G4+Alternatives!$F$29*O4 -> 3.2320323 | AQ4: =I4-AP4 -> -0.20351825
A5: DBX 707 | B5: Aston Martin Lagonda | C5: gas_diesel | D5: 21.5837 | E5: 5500 | F5: 707 | G5: 55.4 | H5: FE file ENG_RATED_HP | I5: =LN(D5) -> 3.0719384 | J5: =LN(E5) -> 8.6125034 | K5: =LN(F5) -> 6.5610307 | L5: 0 | M5: 0 | N5: =G5 -> 55.4 | O5: =L5+M5 -> 0 | P5: =L5+2*M5 -> 0 | Q5: =J5 -> 8.6125034 | R5: =K5 -> 6.5610307 | S5: =G5 -> 55.4 | T5: =O5 -> 0 | U5: =J5 -> 8.6125034 | V5: =K5 -> 6.5610307 | W5: =G5 -> 55.4 | X5: =P5 -> 0 | Y5: =J5 -> 8.6125034 | Z5: =K5 -> 6.5610307 | AA5: =G5 -> 55.4 | AB5: =L5 -> 0 | AC5: =M5 -> 0 | AD5: =M5*J5 -> 0 | AE5: =M5*K5 -> 0 | AF5: =M5*G5 -> 0 | AG5: =J5 -> 8.6125034 | AH5: =L5 -> 0 | AI5: =M5 -> 0 | AJ5: =J5 -> 8.6125034 | AK5: =K5 -> 6.5610307 | AL5: =M5 -> 0 | AM5: =CER!$C$7+CER!$C$8*J5+CER!$C$9*K5+CER!$C$10*L5+CER!$C$11*M5 -> 2.9381793 | AN5: =EXP(AM5) -> 18.881437 | AO5: =I5-AM5 -> 0.13375913 | AP5: =Alternatives!$F$25+Alternatives!$F$26*J5+Alternatives!$F$27*K5+Alternatives!$F$28*G5+Alternatives!$F$29*O5 -> 3.1652088 | AQ5: =I5-AP5 -> -0.093270373
A6: X3 xDrive30i | B6: BMW | C6: gas_diesel | D6: 31.5873 | E6: 4500 | F6: 248 | G6: 49.6 | H6: FE file ENG_RATED_HP | I6: =LN(D6) -> 3.4527551 | J6: =LN(E6) -> 8.4118327 | K6: =LN(F6) -> 5.5134287 | L6: 0 | M6: 0 | N6: =G6 -> 49.6 | O6: =L6+M6 -> 0 | P6: =L6+2*M6 -> 0 | Q6: =J6 -> 8.4118327 | R6: =K6 -> 5.5134287 | S6: =G6 -> 49.6 | T6: =O6 -> 0 | U6: =J6 -> 8.4118327 | V6: =K6 -> 5.5134287 | W6: =G6 -> 49.6 | X6: =P6 -> 0 | Y6: =J6 -> 8.4118327 | Z6: =K6 -> 5.5134287 | AA6: =G6 -> 49.6 | AB6: =L6 -> 0 | AC6: =M6 -> 0 | AD6: =M6*J6 -> 0 | AE6: =M6*K6 -> 0 | AF6: =M6*G6 -> 0 | AG6: =J6 -> 8.4118327 | AH6: =L6 -> 0 | AI6: =M6 -> 0 | AJ6: =J6 -> 8.4118327 | AK6: =K6 -> 5.5134287 | AL6: =M6 -> 0 | AM6: =CER!$C$7+CER!$C$8*J6+CER!$C$9*K6+CER!$C$10*L6+CER!$C$11*M6 -> 3.4155309 | AN6: =EXP(AM6) -> 30.433101 | AO6: =I6-AM6 -> 0.037224275 | AP6: =Alternatives!$F$25+Alternatives!$F$26*J6+Alternatives!$F$27*K6+Alternatives!$F$28*G6+Alternatives!$F$29*O6 -> 3.4451631 | AQ6: =I6-AP6 -> 0.0075920412
A7: X4 xDrive30i | B7: BMW | C7: gas_diesel | D7: 31.5873 | E7: 4500 | F7: 248 | G7: 50.7 | H7: FE file ENG_RATED_HP | I7: =LN(D7) -> 3.4527551 | J7: =LN(E7) -> 8.4118327 | K7: =LN(F7) -> 5.5134287 | L7: 0 | M7: 0 | N7: =G7 -> 50.7 | O7: =L7+M7 -> 0 | P7: =L7+2*M7 -> 0 | Q7: =J7 -> 8.4118327 | R7: =K7 -> 5.5134287 | S7: =G7 -> 50.7 | T7: =O7 -> 0 | U7: =J7 -> 8.4118327 | V7: =K7 -> 5.5134287 | W7: =G7 -> 50.7 | X7: =P7 -> 0 | Y7: =J7 -> 8.4118327 | Z7: =K7 -> 5.5134287 | AA7: =G7 -> 50.7 | AB7: =L7 -> 0 | AC7: =M7 -> 0 | AD7: =M7*J7 -> 0 | AE7: =M7*K7 -> 0 | AF7: =M7*G7 -> 0 | AG7: =J7 -> 8.4118327 | AH7: =L7 -> 0 | AI7: =M7 -> 0 | AJ7: =J7 -> 8.4118327 | AK7: =K7 -> 5.5134287 | AL7: =M7 -> 0 | AM7: =CER!$C$7+CER!$C$8*J7+CER!$C$9*K7+CER!$C$10*L7+CER!$C$11*M7 -> 3.4155309 | AN7: =EXP(AM7) -> 30.433101 | AO7: =I7-AM7 -> 0.037224275 | AP7: =Alternatives!$F$25+Alternatives!$F$26*J7+Alternatives!$F$27*K7+Alternatives!$F$28*G7+Alternatives!$F$29*O7 -> 3.4308551 | AQ7: =I7-AP7 -> 0.021900087
A8: X3 sDrive30i | B8: BMW | C8: gas_diesel | D8: 33.2063 | E8: 4500 | F8: 248 | G8: 50.2 | H8: FE file ENG_RATED_HP | I8: =LN(D8) -> 3.5027396 | J8: =LN(E8) -> 8.4118327 | K8: =LN(F8) -> 5.5134287 | L8: 0 | M8: 0 | N8: =G8 -> 50.2 | O8: =L8+M8 -> 0 | P8: =L8+2*M8 -> 0 | Q8: =J8 -> 8.4118327 | R8: =K8 -> 5.5134287 | S8: =G8 -> 50.2 | T8: =O8 -> 0 | U8: =J8 -> 8.4118327 | V8: =K8 -> 5.5134287 | W8: =G8 -> 50.2 | X8: =P8 -> 0 | Y8: =J8 -> 8.4118327 | Z8: =K8 -> 5.5134287 | AA8: =G8 -> 50.2 | AB8: =L8 -> 0 | AC8: =M8 -> 0 | AD8: =M8*J8 -> 0 | AE8: =M8*K8 -> 0 | AF8: =M8*G8 -> 0 | AG8: =J8 -> 8.4118327 | AH8: =L8 -> 0 | AI8: =M8 -> 0 | AJ8: =J8 -> 8.4118327 | AK8: =K8 -> 5.5134287 | AL8: =M8 -> 0 | AM8: =CER!$C$7+CER!$C$8*J8+CER!$C$9*K8+CER!$C$10*L8+CER!$C$11*M8 -> 3.4155309 | AN8: =EXP(AM8) -> 30.433101 | AO8: =I8-AM8 -> 0.08720875 | AP8: =Alternatives!$F$25+Alternatives!$F$26*J8+Alternatives!$F$27*K8+Alternatives!$F$28*G8+Alternatives!$F$29*O8 -> 3.4373587 | AQ8: =I8-AP8 -> 0.065380906
A9: M850i xDrive Coupe | B9: BMW | C9: gas_diesel | D9: 25.0424 | E9: 4500 | F9: 523 | G9: 49.7 | H9: FE file ENG_RATED_HP | I9: =LN(D9) -> 3.2205704 | J9: =LN(E9) -> 8.4118327 | K9: =LN(F9) -> 6.2595815 | L9: 0 | M9: 0 | N9: =G9 -> 49.7 | O9: =L9+M9 -> 0 | P9: =L9+2*M9 -> 0 | Q9: =J9 -> 8.4118327 | R9: =K9 -> 6.2595815 | S9: =G9 -> 49.7 | T9: =O9 -> 0 | U9: =J9 -> 8.4118327 | V9: =K9 -> 6.2595815 | W9: =G9 -> 49.7 | X9: =P9 -> 0 | Y9: =J9 -> 8.4118327 | Z9: =K9 -> 6.2595815 | AA9: =G9 -> 49.7 | AB9: =L9 -> 0 | AC9: =M9 -> 0 | AD9: =M9*J9 -> 0 | AE9: =M9*K9 -> 0 | AF9: =M9*G9 -> 0 | AG9: =J9 -> 8.4118327 | AH9: =L9 -> 0 | AI9: =M9 -> 0 | AJ9: =J9 -> 8.4118327 | AK9: =K9 -> 6.2595815 | AL9: =M9 -> 0 | AM9: =CER!$C$7+CER!$C$8*J9+CER!$C$9*K9+CER!$C$10*L9+CER!$C$11*M9 -> 3.1402425 | AN9: =EXP(AM9) -> 23.10947 | AO9: =I9-AM9 -> 0.080327877 | AP9: =Alternatives!$F$25+Alternatives!$F$26*J9+Alternatives!$F$27*K9+Alternatives!$F$28*G9+Alternatives!$F$29*O9 -> 3.2453037 | AQ9: =I9-AP9 -> -0.024733304
A10: M850i xDrive Convertible | B10: BMW | C10: gas_diesel | D10: 24.9997 | E10: 5000 | F10: 523 | G10: 49.7 | H10: FE file ENG_RATED_HP | I10: =LN(D10) -> 3.2188638 | J10: =LN(E10) -> 8.5171932 | K10: =LN(F10) -> 6.2595815 | L10: 0 | M10: 0 | N10: =G10 -> 49.7 | O10: =L10+M10 -> 0 | P10: =L10+2*M10 -> 0 | Q10: =J10 -> 8.5171932 | R10: =K10 -> 6.2595815 | S10: =G10 -> 49.7 | T10: =O10 -> 0 | U10: =J10 -> 8.5171932 | V10: =K10 -> 6.2595815 | W10: =G10 -> 49.7 | X10: =P10 -> 0 | Y10: =J10 -> 8.5171932 | Z10: =K10 -> 6.2595815 | AA10: =G10 -> 49.7 | AB10: =L10 -> 0 | AC10: =M10 -> 0 | AD10: =M10*J10 -> 0 | AE10: =M10*K10 -> 0 | AF10: =M10*G10 -> 0 | AG10: =J10 -> 8.5171932 | AH10: =L10 -> 0 | AI10: =M10 -> 0 | AJ10: =J10 -> 8.5171932 | AK10: =K10 -> 6.2595815 | AL10: =M10 -> 0 | AM10: =CER!$C$7+CER!$C$8*J10+CER!$C$9*K10+CER!$C$10*L10+CER!$C$11*M10 -> 3.0925448 | AN10: =EXP(AM10) -> 22.033077 | AO10: =I10-AM10 -> 0.12631898 | AP10: =Alternatives!$F$25+Alternatives!$F$26*J10+Alternatives!$F$27*K10+Alternatives!$F$28*G10+Alternatives!$F$29*O10 -> 3.2842961 | AQ10: =I10-AP10 -> -0.065432317
A11: Z4 sDrive30i | B11: BMW | C11: gas_diesel | D11: 37.762 | E11: 3500 | F11: 255 | G11: 42.9 | H11: FE file ENG_RATED_HP | I11: =LN(D11) -> 3.6313033 | J11: =LN(E11) -> 8.1605182 | K11: =LN(F11) -> 5.5412635 | L11: 0 | M11: 0 | N11: =G11 -> 42.9 | O11: =L11+M11 -> 0 | P11: =L11+2*M11 -> 0 | Q11: =J11 -> 8.1605182 | R11: =K11 -> 5.5412635 | S11: =G11 -> 42.9 | T11: =O11 -> 0 | U11: =J11 -> 8.1605182 | V11: =K11 -> 5.5412635 | W11: =G11 -> 42.9 | X11: =P11 -> 0 | Y11: =J11 -> 8.1605182 | Z11: =K11 -> 5.5412635 | AA11: =G11 -> 42.9 | AB11: =L11 -> 0 | AC11: =M11 -> 0 | AD11: =M11*J11 -> 0 | AE11: =M11*K11 -> 0 | AF11: =M11*G11 -> 0 | AG11: =J11 -> 8.1605182 | AH11: =L11 -> 0 | AI11: =M11 -> 0 | AJ11: =J11 -> 8.1605182 | AK11: =K11 -> 5.5412635 | AL11: =M11 -> 0 | AM11: =CER!$C$7+CER!$C$8*J11+CER!$C$9*K11+CER!$C$10*L11+CER!$C$11*M11 -> 3.5190337 | AN11: =EXP(AM11) -> 33.751799 | AO11: =I11-AM11 -> 0.11226958 | AP11: =Alternatives!$F$25+Alternatives!$F$26*J11+Alternatives!$F$27*K11+Alternatives!$F$28*G11+Alternatives!$F$29*O11 -> 3.431897 | AQ11: =I11-AP11 -> 0.19940626
A12: X3 M | B12: BMW | C12: gas_diesel | D12: 21.7837 | E12: 5000 | F12: 473 | G12: 49.7 | H12: FE file ENG_RATED_HP | I12: =LN(D12) -> 3.081162 | J12: =LN(E12) -> 8.5171932 | K12: =LN(F12) -> 6.1590954 | L12: 0 | M12: 0 | N12: =G12 -> 49.7 | O12: =L12+M12 -> 0 | P12: =L12+2*M12 -> 0 | Q12: =J12 -> 8.5171932 | R12: =K12 -> 6.1590954 | S12: =G12 -> 49.7 | T12: =O12 -> 0 | U12: =J12 -> 8.5171932 | V12: =K12 -> 6.1590954 | W12: =G12 -> 49.7 | X12: =P12 -> 0 | Y12: =J12 -> 8.5171932 | Z12: =K12 -> 6.1590954 | AA12: =G12 -> 49.7 | AB12: =L12 -> 0 | AC12: =M12 -> 0 | AD12: =M12*J12 -> 0 | AE12: =M12*K12 -> 0 | AF12: =M12*G12 -> 0 | AG12: =J12 -> 8.5171932 | AH12: =L12 -> 0 | AI12: =M12 -> 0 | AJ12: =J12 -> 8.5171932 | AK12: =K12 -> 6.1590954 | AL12: =M12 -> 0 | AM12: =CER!$C$7+CER!$C$8*J12+CER!$C$9*K12+CER!$C$10*L12+CER!$C$11*M12 -> 3.1296186 | AN12: =EXP(AM12) -> 22.865256 | AO12: =I12-AM12 -> -0.048456568 | AP12: =Alternatives!$F$25+Alternatives!$F$26*J12+Alternatives!$F$27*K12+Alternatives!$F$28*G12+Alternatives!$F$29*O12 -> 3.3110365 | AQ12: =I12-AP12 -> -0.2298745
A13: X3 M Competition | B13: BMW | C13: gas_diesel | D13: 21.7837 | E13: 5000 | F13: 503 | G13: 49.7 | H13: FE file ENG_RATED_HP | I13: =LN(D13) -> 3.081162 | J13: =LN(E13) -> 8.5171932 | K13: =LN(F13) -> 6.2205902 | L13: 0 | M13: 0 | N13: =G13 -> 49.7 | O13: =L13+M13 -> 0 | P13: =L13+2*M13 -> 0 | Q13: =J13 -> 8.5171932 | R13: =K13 -> 6.2205902 | S13: =G13 -> 49.7 | T13: =O13 -> 0 | U13: =J13 -> 8.5171932 | V13: =K13 -> 6.2205902 | W13: =G13 -> 49.7 | X13: =P13 -> 0 | Y13: =J13 -> 8.5171932 | Z13: =K13 -> 6.2205902 | AA13: =G13 -> 49.7 | AB13: =L13 -> 0 | AC13: =M13 -> 0 | AD13: =M13*J13 -> 0 | AE13: =M13*K13 -> 0 | AF13: =M13*G13 -> 0 | AG13: =J13 -> 8.5171932 | AH13: =L13 -> 0 | AI13: =M13 -> 0 | AJ13: =J13 -> 8.5171932 | AK13: =K13 -> 6.2205902 | AL13: =M13 -> 0 | AM13: =CER!$C$7+CER!$C$8*J13+CER!$C$9*K13+CER!$C$10*L13+CER!$C$11*M13 -> 3.1069304 | AN13: =EXP(AM13) -> 22.352327 | AO13: =I13-AM13 -> -0.025768454 | AP13: =Alternatives!$F$25+Alternatives!$F$26*J13+Alternatives!$F$27*K13+Alternatives!$F$28*G13+Alternatives!$F$29*O13 -> 3.2946721 | AQ13: =I13-AP13 -> -0.21351013
... A1286: Polestar 2 Single Motor (20 Inch Wheels) | B1286: Volvo Car USA, LLC | C1286: bev | D1286: 159.6008 | E1286: 4500 | F1286: 348.5 | G1286: 47 | H1286: Test Car List: tg | I1286: =LN(D1286) -> 5.0726757 | J1286: =LN(E1286) -> 8.4118327 | K1286: =LN(F1286) -> 5.8536382 | L1286: 0 | M1286: 1 | N1286: =G1286 -> 47 | O1286: =L1286+M1286 -> 1 | P1286: =L1286+2*M1286 -> 2 | Q1286: =J1286 -> 8.4118327 | R1286: =K1286 -> 5.8536382 | S1286: =G1286 -> 47 | T1286: =O1286 -> 1 | U1286: =J1286 -> 8.4118327 | V1286: =K1286 -> 5.8536382 | W1286: =G1286 -> 47 | X1286: =P1286 -> 2 | Y1286: =J1286 -> 8.4118327 | Z1286: =K1286 -> 5.8536382 | AA1286: =G1286 -> 47 | AB1286: =L1286 -> 0 | AC1286: =M1286 -> 1 | AD1286: =M1286*J1286 -> 8.4118327 | AE1286: =M1286*K1286 -> 5.8536382 | AF1286: =M1286*G1286 -> 47 | AG1286: =J1286 -> 8.4118327 | AH1286: =L1286 -> 0 | AI1286: =M1286 -> 1 | AJ1286: =J1286 -> 8.4118327 | AK1286: =K1286 -> 5.8536382 | AL1286: =M1286 -> 1 | AM1286: =CER!$C$7+CER!$C$8*J1286+CER!$C$9*K1286+CER!$C$10*L1286+CER!$C$11*M1286 -> 4.9979829 | AN1286: =EXP(AM1286) -> 148.11409 | AO1286: =I1286-AM1286 -> 0.074692844 | AP1286: =Alternatives!$F$25+Alternatives!$F$26*J1286+Alternatives!$F$27*K1286+Alternatives!$F$28*G1286+Alternatives!$F$29*O1286 -> 4.2331889 | AQ1286: =I1286-AP1286 -> 0.83948679

Sheet Data_Combustion
A1: carline | B1: powertrain | C1: MPG | D1: weight_lbs | E1: horsepower | F1: footprint_sqft | G1: hybrid | H1: ln_mpg | I1: ln_weight | J1: ln_hp | K1: footprint | L1: hybrid (block)
A2: DB12 V8 | B2: gas_diesel | C2: 22.4729 | D2: 4500 | E2: 680 | F2: 50 | G2: 0 | H2: =LN(C2) -> 3.1123101 | I2: =LN(D2) -> 8.4118327 | J2: =LN(E2) -> 6.5220928 | K2: =F2 -> 50 | L2: =G2 -> 0
A3: Valour | B3: gas_diesel | C3: 18.3624 | D3: 4000 | E3: 715 | F3: 48.2 | G3: 0 | H3: =LN(C3) -> 2.9103051 | I3: =LN(D3) -> 8.2940496 | J3: =LN(E3) -> 6.5722825 | K3: =F3 -> 48.2 | L3: =G3 -> 0
A4: DBX V8 | B4: gas_diesel | C4: 20.6665 | D4: 5500 | E4: 550 | F4: 55.4 | G4: 0 | H4: =LN(C4) -> 3.028514 | I4: =LN(D4) -> 8.6125034 | J4: =LN(E4) -> 6.3099183 | K4: =F4 -> 55.4 | L4: =G4 -> 0
A5: DBX 707 | B5: gas_diesel | C5: 21.5837 | D5: 5500 | E5: 707 | F5: 55.4 | G5: 0 | H5: =LN(C5) -> 3.0719384 | I5: =LN(D5) -> 8.6125034 | J5: =LN(E5) -> 6.5610307 | K5: =F5 -> 55.4 | L5: =G5 -> 0
A6: X3 xDrive30i | B6: gas_diesel | C6: 31.5873 | D6: 4500 | E6: 248 | F6: 49.6 | G6: 0 | H6: =LN(C6) -> 3.4527551 | I6: =LN(D6) -> 8.4118327 | J6: =LN(E6) -> 5.5134287 | K6: =F6 -> 49.6 | L6: =G6 -> 0
A7: X4 xDrive30i | B7: gas_diesel | C7: 31.5873 | D7: 4500 | E7: 248 | F7: 50.7 | G7: 0 | H7: =LN(C7) -> 3.4527551 | I7: =LN(D7) -> 8.4118327 | J7: =LN(E7) -> 5.5134287 | K7: =F7 -> 50.7 | L7: =G7 -> 0
A8: X3 sDrive30i | B8: gas_diesel | C8: 33.2063 | D8: 4500 | E8: 248 | F8: 50.2 | G8: 0 | H8: =LN(C8) -> 3.5027396 | I8: =LN(D8) -> 8.4118327 | J8: =LN(E8) -> 5.5134287 | K8: =F8 -> 50.2 | L8: =G8 -> 0
A9: M850i xDrive Coupe | B9: gas_diesel | C9: 25.0424 | D9: 4500 | E9: 523 | F9: 49.7 | G9: 0 | H9: =LN(C9) -> 3.2205704 | I9: =LN(D9) -> 8.4118327 | J9: =LN(E9) -> 6.2595815 | K9: =F9 -> 49.7 | L9: =G9 -> 0
A10: M850i xDrive Convertible | B10: gas_diesel | C10: 24.9997 | D10: 5000 | E10: 523 | F10: 49.7 | G10: 0 | H10: =LN(C10) -> 3.2188638 | I10: =LN(D10) -> 8.5171932 | J10: =LN(E10) -> 6.2595815 | K10: =F10 -> 49.7 | L10: =G10 -> 0
A11: Z4 sDrive30i | B11: gas_diesel | C11: 37.762 | D11: 3500 | E11: 255 | F11: 42.9 | G11: 0 | H11: =LN(C11) -> 3.6313033 | I11: =LN(D11) -> 8.1605182 | J11: =LN(E11) -> 5.5412635 | K11: =F11 -> 42.9 | L11: =G11 -> 0
A12: X3 M | B12: gas_diesel | C12: 21.7837 | D12: 5000 | E12: 473 | F12: 49.7 | G12: 0 | H12: =LN(C12) -> 3.081162 | I12: =LN(D12) -> 8.5171932 | J12: =LN(E12) -> 6.1590954 | K12: =F12 -> 49.7 | L12: =G12 -> 0
A13: X3 M Competition | B13: gas_diesel | C13: 21.7837 | D13: 5000 | E13: 503 | F13: 49.7 | G13: 0 | H13: =LN(C13) -> 3.081162 | I13: =LN(D13) -> 8.5171932 | J13: =LN(E13) -> 6.2205902 | K13: =F13 -> 49.7 | L13: =G13 -> 0
... A1026: XC90 B6 AWD | B1026: hybrid | C1026: 29.8831 | D1026: 5000 | E1026: 295 | F1026: 53.5 | G1026: 1 | H1026: =LN(C1026) -> 3.3972931 | I1026: =LN(D1026) -> 8.5171932 | J1026: =LN(E1026) -> 5.6869754 | K1026: =F1026 -> 53.5 | L1026: =G1026 -> 1

Sheet CER
A1: The final CER: ln(MPG) = b0 + b1 ln(weight) + b2 ln(horsepower) + b3 hybrid + b4 electric
A2: Fit by LINEST over Data rows 2 to 1286 (n below). Coefficients, R-squared, F, and SSE match the Python fit exactly; LINEST standard errors are classical OLS, the deck's are HC1 robust (column H).
A3: n (model types) | C3: =COUNT(Data!$I$2:$I$1286) -> 1285
A4: k (predictors) | C4: 4
A6: Term | B6: LINEST column | C6: Coefficient | D6: Std error (OLS, LINEST) | E6: t = coef / SE | F6: p (two-tailed) | G6: Verdict at alpha = 0.05 | H6: HC1 robust SE (deck) | I6: t with HC1 SE
A7: intercept | B7: 5 | C7: =INDEX(LINEST(Data!$I$2:$I$1286,Data!$J$2:$M$1286,TRUE,TRUE),1,5) -> 9.2577891 | D7: =INDEX(LINEST(Data!$I$2:$I$1286,Data!$J$2:$M$1286,TRUE,TRUE),2,5) -> 0.16906959 | E7: =C7/D7 -> 54.757271 | F7: =_xlfn.T.DIST.2T(ABS(E7),$C$17) -> 0 | G7: =IF(F7<0.05,"reject H0: coefficient differs from zero","fail to reject H0") -> reject H0: coefficient differs from zero | H7: 0.2014 | I7: =C7/H7 -> 45.967175
A8: ln(weight) | B8: 4 | C8: =INDEX(LINEST(Data!$I$2:$I$1286,Data!$J$2:$M$1286,TRUE,TRUE),1,4) -> -0.45270912 | D8: =INDEX(LINEST(Data!$I$2:$I$1286,Data!$J$2:$M$1286,TRUE,TRUE),2,4) -> 0.023394081 | E8: =C8/D8 -> -19.351439 | F8: =_xlfn.T.DIST.2T(ABS(E8),$C$17) -> 2.1929529e-73 | G8: =IF(F8<0.05,"reject H0: coefficient differs from zero","fail to reject H0") -> reject H0: coefficient differs from zero | H8: 0.0293 | I8: =C8/H8 -> -15.450823
A9: ln(horsepower) | B9: 3 | C9: =INDEX(LINEST(Data!$I$2:$I$1286,Data!$J$2:$M$1286,TRUE,TRUE),1,3) -> -0.36894371 | D9: =INDEX(LINEST(Data!$I$2:$I$1286,Data!$J$2:$M$1286,TRUE,TRUE),2,3) -> 0.010334543 | E9: =C9/D9 -> -35.700051 | F9: =_xlfn.T.DIST.2T(ABS(E9),$C$17) -> 2.7427466e-194 | G9: =IF(F9<0.05,"reject H0: coefficient differs from zero","fail to reject H0") -> reject H0: coefficient differs from zero | H9: 0.015 | I9: =C9/H9 -> -24.596248
A10: hybrid | B10: 2 | C10: =INDEX(LINEST(Data!$I$2:$I$1286,Data!$J$2:$M$1286,TRUE,TRUE),1,2) -> 0.22375357 | D10: =INDEX(LINEST(Data!$I$2:$I$1286,Data!$J$2:$M$1286,TRUE,TRUE),2,2) -> 0.010114394 | E10: =C10/D10 -> 22.122291 | F10: =_xlfn.T.DIST.2T(ABS(E10),$C$17) -> 4.2938087e-92 | G10: =IF(F10<0.05,"reject H0: coefficient differs from zero","fail to reject H0") -> reject H0: coefficient differs from zero | H10: 0.0107 | I10: =C10/H10 -> 20.911549
A11: battery-electric | B11: 1 | C11: =INDEX(LINEST(Data!$I$2:$I$1286,Data!$J$2:$M$1286,TRUE,TRUE),1,1) -> 1.7079701 | D11: =INDEX(LINEST(Data!$I$2:$I$1286,Data!$J$2:$M$1286,TRUE,TRUE),2,1) -> 0.010927903 | E11: =C11/D11 -> 156.29441 | F11: =_xlfn.T.DIST.2T(ABS(E11),$C$17) -> 0 | G11: =IF(F11<0.05,"reject H0: coefficient differs from zero","fail to reject H0") -> reject H0: coefficient differs from zero | H11: 0.0145 | I11: =C11/H11 -> 117.79104
A12: Note: LINEST lists coefficients in reverse order (last predictor first, intercept last); column B is the LINEST column each term is read from with INDEX.
A14: Whole-model fit
A15: R-squared | C15: =INDEX(LINEST(Data!$I$2:$I$1286,Data!$J$2:$M$1286,TRUE,TRUE),3,1) -> 0.954622
A16: Adjusted R-squared | C16: =1-(1-C15)*(C3-1)/(C3-C4-1) -> 0.95448019
A17: Residual degrees of freedom | C17: =INDEX(LINEST(Data!$I$2:$I$1286,Data!$J$2:$M$1286,TRUE,TRUE),4,2) -> 1280
A18: F statistic (whole model, H0: all four coefficients are zero) | C18: =INDEX(LINEST(Data!$I$2:$I$1286,Data!$J$2:$M$1286,TRUE,TRUE),4,1) -> 6731.8746
A19: F p-value | C19: =_xlfn.F.DIST.RT(C18,C4,C17) -> 0
A20: F recomputed from R-squared: (R2/k) / ((1-R2)/df) | C20: =(C15/C4)/((1-C15)/C17) -> 6731.8746
A21: Regression sum of squares | C21: =INDEX(LINEST(Data!$I$2:$I$1286,Data!$J$2:$M$1286,TRUE,TRUE),5,1) -> 493.78259
A22: Residual sum of squares (SSE) | C22: =INDEX(LINEST(Data!$I$2:$I$1286,Data!$J$2:$M$1286,TRUE,TRUE),5,2) -> 23.471981
A23: Residual standard error s (log units) | C23: =INDEX(LINEST(Data!$I$2:$I$1286,Data!$J$2:$M$1286,TRUE,TRUE),3,2) -> 0.13541597
A25: Reading the coefficients (elasticities and premiums)
A26: MPG change for 10% more weight, elasticity reading b1 x 10% (the deck's figure) | C26: =C8*0.1 -> -0.045270912
A27: MPG change for 10% more horsepower, elasticity reading b2 x 10% (the deck's figure) | C27: =C9*0.1 -> -0.036894371
A28: Hybrid premium at identical weight and power, exp(b3) - 1 | C28: =EXP(C10)-1 -> 0.25076276
A29: Battery-electric premium, exp(b4) - 1, in MPG-equivalent | C29: =EXP(C11)-1 -> 4.5177498
A30: Exact power-law reading for 10% more weight, 1.1^b1 - 1 (elasticity is the first-order approximation) | C30: =1.1^C8-1 -> -0.042230167
A31: Exact power-law reading for 10% more horsepower, 1.1^b2 - 1 | C31: =1.1^C9-1 -> -0.034553019
A33: Variance inflation factors: VIF_j = 1 / (1 - R2 of predictor j regressed on the other three)
A34: ln(weight) | C34: =1/(1-INDEX(LINEST(Data!$J$2:$J$1286,Data!$K$2:$M$1286,TRUE,TRUE),3,1)) -> 1.8961715
A35: ln(horsepower) | C35: =1/(1-INDEX(LINEST(Data!$K$2:$K$1286,Data!$AG$2:$AI$1286,TRUE,TRUE),3,1)) -> 1.628217
A36: hybrid | C36: =1/(1-INDEX(LINEST(Data!$L$2:$L$1286,Data!$AJ$2:$AL$1286,TRUE,TRUE),3,1)) -> 1.1233555
A37: battery-electric | C37: =1/(1-INDEX(LINEST(Data!$M$2:$M$1286,Data!$J$2:$L$1286,TRUE,TRUE),3,1)) -> 1.3506038
A39: Prediction band (in logs, leverage ignored)
A40: Typical miss, exp(s) - 1 | C40: =EXP(C23)-1 -> 0.14501298
A41: 95% band factor, exp(1.96 s): predicted times or divided by | C41: =EXP(1.96*C23) -> 1.3039724
A42: Share of model types inside the band | C42: =SUMPRODUCT(--(ABS(Data!$AO$2:$AO$1286)<=1.96*C23))/C3 -> 0.9385214
A45: Named outliers on the predicted-vs-actual slide (looked up live from Data)
A46: carline | B46: powertrain | C46: actual | D46: predicted | E46: actual / predicted | F46: residual / s
A47: VF 8 Plus | B47: =INDEX(Data!$C$2:$C$1286,MATCH(A47,Data!$A$2:$A$1286,0)) -> bev | C47: =INDEX(Data!$D$2:$D$1286,MATCH(A47,Data!$A$2:$A$1286,0)) -> 62.3061 | D47: =INDEX(Data!$AN$2:$AN$1286,MATCH(A47,Data!$A$2:$A$1286,0)) -> 123.35375 | E47: =C47/D47 -> 0.50510096 | F47: =INDEX(Data!$AO$2:$AO$1286,MATCH(A47,Data!$A$2:$A$1286,0))/$C$23 -> -5.0436957
...

Sheet Alternatives
A1: Alternative CERs, each fit with LINEST, and the nested F-tests between them
A2: Nested F = ((SSE_restricted - SSE_full) / q) / (SSE_full / df_full), where q is the number of restrictions; p from F.DIST.RT.
A4: Spec A: Combustion only (original CER): ln(weight), ln(HP), footprint, hybrid; n = 1,025
A5: n | C5: =COUNT(Data_Combustion!$H$2:$H$1026) -> 1025 | E5: Term | F5: Coefficient | G5: SE (OLS) | H5: t
A6: R-squared | C6: =INDEX(LINEST(Data_Combustion!$H$2:$H$1026,Data_Combustion!$I$2:$L$1026,TRUE,TRUE),3,1) -> 0.84603748 | E6: intercept | F6: =INDEX(LINEST(Data_Combustion!$H$2:$H$1026,Data_Combustion!$I$2:$L$1026,TRUE,TRUE),1,5) -> 8.7774826 | G6: =INDEX(LINEST(Data_Combustion!$H$2:$H$1026,Data_Combustion!$I$2:$L$1026,TRUE,TRUE),2,5) -> 0.22042489 | H6: =F6/G6 -> 39.820741
A7: Adjusted R-squared | C7: =1-(1-C6)*(C5-1)/(C5-4-1) -> 0.84543371 | E7: ln(weight) | F7: =INDEX(LINEST(Data_Combustion!$H$2:$H$1026,Data_Combustion!$I$2:$L$1026,TRUE,TRUE),1,4) -> -0.30375764 | G7: =INDEX(LINEST(Data_Combustion!$H$2:$H$1026,Data_Combustion!$I$2:$L$1026,TRUE,TRUE),2,4) -> 0.032739556 | H7: =F7/G7 -> -9.2780011
A8: F (whole model) | C8: =INDEX(LINEST(Data_Combustion!$H$2:$H$1026,Data_Combustion!$I$2:$L$1026,TRUE,TRUE),4,1) -> 1401.2473 | E8: ln(horsepower) | F8: =INDEX(LINEST(Data_Combustion!$H$2:$H$1026,Data_Combustion!$I$2:$L$1026,TRUE,TRUE),1,3) -> -0.48301416 | G8: =INDEX(LINEST(Data_Combustion!$H$2:$H$1026,Data_Combustion!$I$2:$L$1026,TRUE,TRUE),2,3) -> 0.010100109 | H8: =F8/G8 -> -47.82267
A9: Residual df | C9: =INDEX(LINEST(Data_Combustion!$H$2:$H$1026,Data_Combustion!$I$2:$L$1026,TRUE,TRUE),4,2) -> 1020 | E9: footprint | F9: =INDEX(LINEST(Data_Combustion!$H$2:$H$1026,Data_Combustion!$I$2:$L$1026,TRUE,TRUE),1,2) -> -0.0022273382 | G9: =INDEX(LINEST(Data_Combustion!$H$2:$H$1026,Data_Combustion!$I$2:$L$1026,TRUE,TRUE),2,2) -> 0.00077527425 | H9: =F9/G9 -> -2.8729681
A10: SSE | C10: =INDEX(LINEST(Data_Combustion!$H$2:$H$1026,Data_Combustion!$I$2:$L$1026,TRUE,TRUE),5,2) -> 13.153763 | E10: hybrid | F10: =INDEX(LINEST(Data_Combustion!$H$2:$H$1026,Data_Combustion!$I$2:$L$1026,TRUE,TRUE),1,1) -> 0.20740284 | G10: =INDEX(LINEST(Data_Combustion!$H$2:$H$1026,Data_Combustion!$I$2:$L$1026,TRUE,TRUE),2,1) -> 0.0087264189 | H10: =F10/G10 -> 23.767234
A13: Spec B: Pooled, powertrain factor plus footprint: ln(weight), ln(HP), hybrid, bev, footprint
A14: n | C14: =COUNT(Data!$I$2:$I$1286) -> 1285 | E14: Term | F14: Coefficient | G14: SE (OLS) | H14: t
A15: R-squared | C15: =INDEX(LINEST(Data!$I$2:$I$1286,Data!$J$2:$N$1286,TRUE,TRUE),3,1) -> 0.95462292 | E15: intercept | F15: =INDEX(LINEST(Data!$I$2:$I$1286,Data!$J$2:$N$1286,TRUE,TRUE),1,6) -> 9.2305493 | G15: =INDEX(LINEST(Data!$I$2:$I$1286,Data!$J$2:$N$1286,TRUE,TRUE),2,6) -> 0.2386676 | H15: =F15/G15 -> 38.675335
A16: Adjusted R-squared | C16: =1-(1-C15)*(C14-1)/(C14-5-1) -> 0.95444553 | E16: ln(weight) | F16: =INDEX(LINEST(Data!$I$2:$I$1286,Data!$J$2:$N$1286,TRUE,TRUE),1,5) -> -0.44837275 | G16: =INDEX(LINEST(Data!$I$2:$I$1286,Data!$J$2:$N$1286,TRUE,TRUE),2,5) -> 0.035585109 | H16: =F16/G16 -> -12.60001
A17: F (whole model) | C17: =INDEX(LINEST(Data!$I$2:$I$1286,Data!$J$2:$N$1286,TRUE,TRUE),4,1) -> 5381.4076 | E17: ln(horsepower) | F17: =INDEX(LINEST(Data!$I$2:$I$1286,Data!$J$2:$N$1286,TRUE,TRUE),1,4) -> -0.36926557 | G17: =INDEX(LINEST(Data!$I$2:$I$1286,Data!$J$2:$N$1286,TRUE,TRUE),2,4) -> 0.010528195 | H17: =F17/G17 -> -35.073969
A18: Residual df | C18: =INDEX(LINEST(Data!$I$2:$I$1286,Data!$J$2:$N$1286,TRUE,TRUE),4,2) -> 1279 | E18: hybrid | F18: =INDEX(LINEST(Data!$I$2:$I$1286,Data!$J$2:$N$1286,TRUE,TRUE),1,3) -> 0.22343156 | G18: =INDEX(LINEST(Data!$I$2:$I$1286,Data!$J$2:$N$1286,TRUE,TRUE),2,3) -> 0.010312194 | H18: =F18/G18 -> 21.666734
A19: SSE | C19: =INDEX(LINEST(Data!$I$2:$I$1286,Data!$J$2:$N$1286,TRUE,TRUE),5,2) -> 23.4715 | E19: battery-electric | F19: =INDEX(LINEST(Data!$I$2:$I$1286,Data!$J$2:$N$1286,TRUE,TRUE),1,2) -> 1.7073917 | G19: =INDEX(LINEST(Data!$I$2:$I$1286,Data!$J$2:$N$1286,TRUE,TRUE),2,2) -> 0.011502065 | H19: =F19/G19 -> 148.44219
E20: footprint | F20: =INDEX(LINEST(Data!$I$2:$I$1286,Data!$J$2:$N$1286,TRUE,TRUE),1,1) -> -0.00014119074 | G20: =INDEX(LINEST(Data!$I$2:$I$1286,Data!$J$2:$N$1286,TRUE,TRUE),2,1) -> 0.00087281771 | H20: =F20/G20 -> -0.1617643
A23: Spec C: Pooled, ONE merged electrified flag (hybrid or bev): ln(weight), ln(HP), footprint, electrified
A24: n | C24: =COUNT(Data!$I$2:$I$1286) -> 1285 | E24: Term | F24: Coefficient | G24: SE (OLS) | H24: t
A25: R-squared | C25: =INDEX(LINEST(Data!$I$2:$I$1286,Data!$Q$2:$T$1286,TRUE,TRUE),3,1) -> 0.46508851 | E25: intercept | F25: =INDEX(LINEST(Data!$I$2:$I$1286,Data!$Q$2:$T$1286,TRUE,TRUE),1,5) -> 2.4444029 | G25: =INDEX(LINEST(Data!$I$2:$I$1286,Data!$Q$2:$T$1286,TRUE,TRUE),2,5) -> 0.79475868 | H25: =F25/G25 -> 3.0756543
A26: Adjusted R-squared | C26: =1-(1-C25)*(C24-1)/(C24-4-1) -> 0.46341691 | E26: ln(weight) | F26: =INDEX(LINEST(Data!$I$2:$I$1286,Data!$Q$2:$T$1286,TRUE,TRUE),1,4) -> 0.37008598 | G26: =INDEX(LINEST(Data!$I$2:$I$1286,Data!$Q$2:$T$1286,TRUE,TRUE),2,4) -> 0.11976566 | H26: =F26/G26 -> 3.0900841
A27: F (whole model) | C27: =INDEX(LINEST(Data!$I$2:$I$1286,Data!$Q$2:$T$1286,TRUE,TRUE),4,1) -> 278.22981 | E27: ln(horsepower) | F27: =INDEX(LINEST(Data!$I$2:$I$1286,Data!$Q$2:$T$1286,TRUE,TRUE),1,3) -> -0.26610997 | G27: =INDEX(LINEST(Data!$I$2:$I$1286,Data!$Q$2:$T$1286,TRUE,TRUE),2,3) -> 0.036007319 | H27: =F27/G27 -> -7.3904409
A28: Residual df | C28: =INDEX(LINEST(Data!$I$2:$I$1286,Data!$Q$2:$T$1286,TRUE,TRUE),4,2) -> 1280 | E28: footprint | F28: =INDEX(LINEST(Data!$I$2:$I$1286,Data!$Q$2:$T$1286,TRUE,TRUE),1,2) -> -0.013007315 | G28: =INDEX(LINEST(Data!$I$2:$I$1286,Data!$Q$2:$T$1286,TRUE,TRUE),2,2) -> 0.0029718689 | H28: =F28/G28 -> -4.376813
A29: SSE | C29: =INDEX(LINEST(Data!$I$2:$I$1286,Data!$Q$2:$T$1286,TRUE,TRUE),5,2) -> 276.68542 | E29: electrified | F29: =INDEX(LINEST(Data!$I$2:$I$1286,Data!$Q$2:$T$1286,TRUE,TRUE),1,1) -> 0.84473993 | G29: =INDEX(LINEST(Data!$I$2:$I$1286,Data!$Q$2:$T$1286,TRUE,TRUE),2,1) -> 0.030381763 | H29: =F29/G29 -> 27.804178
A32: Spec D: Pooled, ordinal electrification 0/1/2: ln(weight), ln(HP), footprint, ordinal
A33: n | C33: =COUNT(Data!$I$2:$I$1286) -> 1285 | E33: Term | F33: Coefficient | G33: SE (OLS) | H33: t
A34: R-squared | C34: =INDEX(LINEST(Data!$I$2:$I$1286,Data!$U$2:$X$1286,TRUE,TRUE),3,1) -> 0.81354258 | E34: intercept | F34: =INDEX(LINEST(Data!$I$2:$I$1286,Data!$U$2:$X$1286,TRUE,TRUE),1,5) -> 9.0244752 | G34: =INDEX(LINEST(Data!$I$2:$I$1286,Data!$U$2:$X$1286,TRUE,TRUE),2,5) -> 0.48356473 | H34: =F34/G34 -> 18.662393
A35: Adjusted R-squared | C35: =1-(1-C34)*(C33-1)/(C33-4-1) -> 0.8129599 | E35: ln(weight) | F35: =INDEX(LINEST(Data!$I$2:$I$1286,Data!$U$2:$X$1286,TRUE,TRUE),1,4) -> -0.50715421 | G35: =INDEX(LINEST(Data!$I$2:$I$1286,Data!$U$2:$X$1286,TRUE,TRUE),2,4) -> 0.072081052 | H35: =F35/G35 -> -7.035888
A36: F (whole model) | C36: =INDEX(LINEST(Data!$I$2:$I$1286,Data!$U$2:$X$1286,TRUE,TRUE),4,1) -> 1396.2095 | E36: ln(horsepower) | F36: =INDEX(LINEST(Data!$I$2:$I$1286,Data!$U$2:$X$1286,TRUE,TRUE),1,3) -> -0.27031535 | G36: =INDEX(LINEST(Data!$I$2:$I$1286,Data!$U$2:$X$1286,TRUE,TRUE),2,3) -> 0.021094911 | H36: =F36/G36 -> -12.814245
A37: Residual df | C37: =INDEX(LINEST(Data!$I$2:$I$1286,Data!$U$2:$X$1286,TRUE,TRUE),4,2) -> 1280 | E37: footprint | F37: =INDEX(LINEST(Data!$I$2:$I$1286,Data!$U$2:$X$1286,TRUE,TRUE),1,2) -> 0.00097458916 | G37: =INDEX(LINEST(Data!$I$2:$I$1286,Data!$U$2:$X$1286,TRUE,TRUE),2,2) -> 0.0017682194 | H37: =F37/G37 -> 0.55116981
A38: SSE | C38: =INDEX(LINEST(Data!$I$2:$I$1286,Data!$U$2:$X$1286,TRUE,TRUE),5,2) -> 96.445953 | E38: ordinal 0/1/2 | F38: =INDEX(LINEST(Data!$I$2:$I$1286,Data!$U$2:$X$1286,TRUE,TRUE),1,1) -> 0.76969357 | G38: =INDEX(LINEST(Data!$I$2:$I$1286,Data!$U$2:$X$1286,TRUE,TRUE),2,1) -> 0.011336344 | H38: =F38/G38 -> 67.896103
A41: Spec E: B plus bev-specific slopes: adds bev x ln(weight), bev x ln(HP), bev x footprint
A42: n | C42: =COUNT(Data!$I$2:$I$1286) -> 1285 | E42: Term | F42: Coefficient | G42: SE (OLS) | H42: t
A43: R-squared | C43: =INDEX(LINEST(Data!$I$2:$I$1286,Data!$Y$2:$AF$1286,TRUE,TRUE),3,1) -> 0.96804523 | E43: intercept | F43: =INDEX(LINEST(Data!$I$2:$I$1286,Data!$Y$2:$AF$1286,TRUE,TRUE),1,9) -> 8.7774826 | G43: =INDEX(LINEST(Data!$I$2:$I$1286,Data!$Y$2:$AF$1286,TRUE,TRUE),2,9) -> 0.22091762 | H43: =F43/G43 -> 39.731925
A44: Adjusted R-squared | C44: =1-(1-C43)*(C42-1)/(C42-8-1) -> 0.96784489 | E44: ln(weight) | F44: =INDEX(LINEST(Data!$I$2:$I$1286,Data!$Y$2:$AF$1286,TRUE,TRUE),1,8) -> -0.30375764 | G44: =INDEX(LINEST(Data!$I$2:$I$1286,Data!$Y$2:$AF$1286,TRUE,TRUE),2,8) -> 0.032812741 | H44: =F44/G44 -> -9.2573077
A45: F (whole model) | C45: =INDEX(LINEST(Data!$I$2:$I$1286,Data!$Y$2:$AF$1286,TRUE,TRUE),4,1) -> 4831.9307 | E45: ln(horsepower) | F45: =INDEX(LINEST(Data!$I$2:$I$1286,Data!$Y$2:$AF$1286,TRUE,TRUE),1,7) -> -0.48301416 | G45: =INDEX(LINEST(Data!$I$2:$I$1286,Data!$Y$2:$AF$1286,TRUE,TRUE),2,7) -> 0.010122686 | H45: =F45/G45 -> -47.716007
A46: Residual df | C46: =INDEX(LINEST(Data!$I$2:$I$1286,Data!$Y$2:$AF$1286,TRUE,TRUE),4,2) -> 1276 | E46: footprint | F46: =INDEX(LINEST(Data!$I$2:$I$1286,Data!$Y$2:$AF$1286,TRUE,TRUE),1,6) -> -0.0022273382 | G46: =INDEX(LINEST(Data!$I$2:$I$1286,Data!$Y$2:$AF$1286,TRUE,TRUE),2,6) -> 0.00077700727 | H46: =F46/G46 -> -2.8665603
A47: SSE | C47: =INDEX(LINEST(Data!$I$2:$I$1286,Data!$Y$2:$AF$1286,TRUE,TRUE),5,2) -> 16.528749 | E47: hybrid | F47: =INDEX(LINEST(Data!$I$2:$I$1286,Data!$Y$2:$AF$1286,TRUE,TRUE),1,5) -> 0.20740284 | G47: =INDEX(LINEST(Data!$I$2:$I$1286,Data!$Y$2:$AF$1286,TRUE,TRUE),2,5) -> 0.0087459257 | H47: =F47/G47 -> 23.714224
E48: battery-electric | F48: =INDEX(LINEST(Data!$I$2:$I$1286,Data!$Y$2:$AF$1286,TRUE,TRUE),1,4) -> 4.8478824 | G48: =INDEX(LINEST(Data!$I$2:$I$1286,Data!$Y$2:$AF$1286,TRUE,TRUE),2,4) -> 0.55738184 | H48: =F48/G48 -> 8.6975966
E49: bev x ln(weight) | F49: =INDEX(LINEST(Data!$I$2:$I$1286,Data!$Y$2:$AF$1286,TRUE,TRUE),1,3) -> -0.7493466 | G49: =INDEX(LINEST(Data!$I$2:$I$1286,Data!$Y$2:$AF$1286,TRUE,TRUE),2,3) -> 0.082563013 | H49: =F49/G49 -> -9.0760569
...

Sheet Normalization
A1: Design-normalized fleet MPG: MPG_norm(t) = MPG(t) x (weight_t / weight_2024)^e_w x (HP_t / HP_2024)^e_h
A2: e_w and e_h are the CER's weight and horsepower elasticities (absolute values of CER!C8 and CER!C9). Fleet averages are production-weighted, EPA Automotive Trends, 1975 to 2024.
A3: e_w (weight elasticity) | C3: =ABS(CER!C8) -> 0.45270912
A4: e_h (horsepower elasticity) | C4: =ABS(CER!C9) -> 0.36894371
A5: 2024 fleet weight (lbs) | C5: =INDEX(C9:C58,MATCH(2024,A9:A58,0)) -> 4353.748
A6: 2024 fleet horsepower | C6: =INDEX(D9:D58,MATCH(2024,A9:A58,0)) -> 258.0114
A8: model year | B8: fleet MPG (raw) | C8: fleet weight (lbs) | D8: fleet HP | E8: weight factor | F8: HP factor | G8: MPG normalized to 2024 design | H8: ln(normalized) | J8: Trend fit: ln(normalized MPG) on model year
A9: 1975 | B9: 13.0597 | C9: 4060.399 | D9: 137.3346 | E9: =(C9/$C$5)^$C$3 -> 0.96891431 | F9: =(D9/$C$6)^$C$4 -> 0.79243102 | G9: =B9*E9*F9 -> 10.027208 | H9: =LN(G9) -> 2.3053022 | J9: Window | K9: 1975 to 2024 | L9: 2005 to 2024
A10: 1976 | B10: 14.22136 | C10: 4079.198 | D10: 135.0839 | E10: =(C10/$C$5)^$C$3 -> 0.97094256 | F10: =(D10/$C$6)^$C$4 -> 0.78761466 | G10: =B10*E10*F10 -> 10.875481 | H10: =LN(G10) -> 2.3865108 | J10: slope (per year, log units) | K10: =INDEX(LINEST(H9:H58,A9:A58,TRUE,TRUE),1,1) -> 0.017738874 | L10: =INDEX(LINEST(H39:H58,A39:A58,TRUE,TRUE),1,1) -> 0.021662592
A11: 1977 | B11: 15.06743 | C11: 3981.818 | D11: 135.9847 | E11: =(C11/$C$5)^$C$3 -> 0.96037996 | F11: =(D11/$C$6)^$C$4 -> 0.78954835 | G11: =B11*E11*F11 -> 11.425126 | H11: =LN(G11) -> 2.435815 | J11: intercept | K11: =INDEX(LINEST(H9:H58,A9:A58,TRUE,TRUE),1,2) -> -32.634981 | L11: =INDEX(LINEST(H39:H58,A39:A58,TRUE,TRUE),1,2) -> -40.538341
A12: 1978 | B12: 15.83777 | C12: 3715.238 | D12: 129.0248 | E12: =(C12/$C$5)^$C$3 -> 0.93071971 | F12: =(D12/$C$6)^$C$4 -> 0.77439153 | G12: =B12*E12*F12 -> 11.414938 | H12: =LN(G12) -> 2.4349228 | J12: R-squared of the trend line | K12: =INDEX(LINEST(H9:H58,A9:A58,TRUE,TRUE),3,1) -> 0.97954874 | L12: =INDEX(LINEST(H39:H58,A39:A58,TRUE,TRUE),3,1) -> 0.98473022
A13: 1979 | B13: 15.91271 | C13: 3655.465 | D13: 123.5922 | E13: =(C13/$C$5)^$C$3 -> 0.92391076 | F13: =(D13/$C$6)^$C$4 -> 0.76219824 | G13: =B13*E13*F13 -> 11.205781 | H13: =LN(G13) -> 2.4164298 | J13: growth per year, exp(slope) - 1 | K13: =EXP(K10)-1 -> 0.017897142 | L13: =EXP(L10)-1 -> 0.02189893
A14: 1980 | B14: 19.16493 | C14: 3227.876 | D14: 103.8276 | E14: =(C14/$C$5)^$C$3 -> 0.87331729 | F14: =(D14/$C$6)^$C$4 -> 0.71473809 | G14: =B14*E14*F14 -> 11.962618 | H14: =LN(G14) -> 2.4817866 | J14: projected 2035 | K14: =EXP(K11+K10*2035) -> 31.932604 | L14: =EXP(L11+L10*2035) -> 34.640887
A15: 1981 | B15: 20.52057 | C15: 3201.759 | D15: 102.1236 | E15: =(C15/$C$5)^$C$3 -> 0.8701113 | F15: =(D15/$C$6)^$C$4 -> 0.71038771 | G15: =B15*E15*F15 -> 12.6841 | H15: =LN(G15) -> 2.5403493 | J15: projected 2045 | K15: =EXP(K11+K10*2045) -> 38.130569 | L15: =EXP(L11+L10*2045) -> 43.019806
A16: 1982 | B16: 21.07205 | C16: 3201.843 | D16: 102.9528 | E16: =(C16/$C$5)^$C$3 -> 0.87012164 | F16: =(D16/$C$6)^$C$4 -> 0.71251037 | G16: =B16*E16*F16 -> 13.064053 | H16: =LN(G16) -> 2.5698644
A17: 1983 | B17: 20.95239 | C17: 3257.34 | D17: 106.9483 | E17: =(C17/$C$5)^$C$3 -> 0.87691715 | F17: =(D17/$C$6)^$C$4 -> 0.72258999 | G17: =B17*E17*F17 -> 13.276514 | H17: =LN(G17) -> 2.5859966 | J17: Normalized path (the trough vanishes) | K17: raw MPG | L17: normalized
A18: 1984 | B18: 21.00023 | C18: 3261.576 | D18: 108.5963 | E18: =(C18/$C$5)^$C$3 -> 0.87743323 | F18: =(D18/$C$6)^$C$4 -> 0.72667823 | G18: =B18*E18*F18 -> 13.389991 | H18: =LN(G18) -> 2.5945075 | J18: 1975 | K18: =INDEX(B9:B58,MATCH(J18,A9:A58,0)) -> 13.0597 | L18: =INDEX(G9:G58,MATCH(J18,A9:A58,0)) -> 10.027208
A19: 1985 | B19: 21.31942 | C19: 3271.127 | D19: 114.1306 | E19: =(C19/$C$5)^$C$3 -> 0.8785955 | F19: =(D19/$C$6)^$C$4 -> 0.74012753 | G19: =B19*E19*F19 -> 13.863437 | H19: =LN(G19) -> 2.629255 | J19: 1987 | K19: =INDEX(B9:B58,MATCH(J19,A9:A58,0)) -> 21.97197 | L19: =INDEX(G9:G58,MATCH(J19,A9:A58,0)) -> 14.346651
A20: 1986 | B20: 21.84433 | C20: 3237.974 | D20: 114.3758 | E20: =(C20/$C$5)^$C$3 -> 0.87455306 | F20: =(D20/$C$6)^$C$4 -> 0.7407138 | G20: =B20*E20*F20 -> 14.150615 | H20: =LN(G20) -> 2.6497581 | J20: 2004 | K20: =INDEX(B9:B58,MATCH(J20,A9:A58,0)) -> 19.2986 | L20: =INDEX(G9:G58,MATCH(J20,A9:A58,0)) -> 17.444399
A21: 1987 | B21: 21.97197 | C21: 3220.507 | D21: 117.6397 | E21: =(C21/$C$5)^$C$3 -> 0.87241415 | F21: =(D21/$C$6)^$C$4 -> 0.74844318 | G21: =B21*E21*F21 -> 14.346651 | H21: =LN(G21) -> 2.6635165 | J21: 2024 | K21: =INDEX(B9:B58,MATCH(J21,A9:A58,0)) -> 27.24521 | L21: =INDEX(G9:G58,MATCH(J21,A9:A58,0)) -> 27.24521
A22: 1988 | B22: 21.86353 | C22: 3283.465 | D22: 123.469 | E22: =(C22/$C$5)^$C$3 -> 0.88009417 | F22: =(D22/$C$6)^$C$4 -> 0.76191784 | G22: =B22*E22*F22 -> 14.660797 | H22: =LN(G22) -> 2.685177
A23: 1989 | B23: 21.42049 | C23: 3351.457 | D23: 128.748 | E23: =(C23/$C$5)^$C$3 -> 0.88829829 | F23: =(D23/$C$6)^$C$4 -> 0.77377819 | G23: =B23*E23*F23 -> 14.723285 | H23: =LN(G23) -> 2.6894302 | J23: Worked example, 1987 (the deck's normalization slide)
A24: 1990 | B24: 21.15752 | C24: 3426.038 | D24: 135.3422 | E24: =(C24/$C$5)^$C$3 -> 0.89719338 | F24: =(D24/$C$6)^$C$4 -> 0.78816997 | G24: =B24*E24*F24 -> 14.961347 | H24: =LN(G24) -> 2.70547 | J24: raw 1987 fleet MPG | K24: =B21 -> 21.97197
A25: 1991 | B25: 21.25642 | C25: 3409.555 | D25: 137.9169 | E25: =(C25/$C$5)^$C$3 -> 0.89523668 | F25: =(D25/$C$6)^$C$4 -> 0.79366899 | G25: =B25*E25*F25 -> 15.103145 | H25: =LN(G25) -> 2.714903 | J25: weight factor (3221/4354)^e_w | K25: =E21 -> 0.87241415
A26: 1992 | B26: 20.79365 | C26: 3512.305 | D26: 145.2572 | E26: =(C26/$C$5)^$C$3 -> 0.90735103 | F26: =(D26/$C$6)^$C$4 -> 0.8089992 | G26: =B26*E26*F26 -> 15.263501 | H26: =LN(G26) -> 2.7254644 | J26: HP factor (118/258)^e_h | K26: =F21 -> 0.74844318
A27: 1993 | B27: 20.8794 | C27: 3518.93 | D27: 146.8406 | E27: =(C27/$C$5)^$C$3 -> 0.90812543 | F27: =(D27/$C$6)^$C$4 -> 0.81224165 | G27: =B27*E27*F27 -> 15.401007 | H27: =LN(G27) -> 2.7344329 | J27: normalized 1987 MPG | K27: =G21 -> 14.346651
A28: 1994 | B28: 20.37752 | C28: 3603.432 | D28: 152.2823 | E28: =(C28/$C$5)^$C$3 -> 0.91793372 | F28: =(D28/$C$6)^$C$4 -> 0.82321974 | G28: =B28*E28*F28 -> 15.3985 | H28: =LN(G28) -> 2.7342701
A29: 1995 | B29: 20.48563 | C29: 3612.509 | D29: 158.1889 | E29: =(C29/$C$5)^$C$3 -> 0.91897978 | F29: =(D29/$C$6)^$C$4 -> 0.83485904 | G29: =B29*E29*F29 -> 15.716956 | H29: =LN(G29) -> 2.7547401
A30: 1996 | B30: 20.43168 | C30: 3658.786 | D30: 163.9606 | E30: =(C30/$C$5)^$C$3 -> 0.92429066 | F30: =(D30/$C$6)^$C$4 -> 0.84597047 | G30: =B30*E30*F30 -> 15.975993 | H30: =LN(G30) -> 2.7710871
A31: 1997 | B31: 20.15038 | C31: 3727.285 | D31: 169.2409 | E31: =(C31/$C$5)^$C$3 -> 0.93208476 | F31: =(D31/$C$6)^$C$4 -> 0.85592167 | G31: =B31*E31*F31 -> 16.075803 | H31: =LN(G31) -> 2.7773152
A32: 1998 | B32: 20.09648 | C32: 3744.005 | D32: 171.471 | E32: =(C32/$C$5)^$C$3 -> 0.9339753 | F32: =(D32/$C$6)^$C$4 -> 0.86006564 | G32: =B32*E32*F32 -> 16.143102 | H32: =LN(G32) -> 2.7814928
A33: 1999 | B33: 19.69506 | C33: 3835.375 | D33: 178.902 | E33: =(C33/$C$5)^$C$3 -> 0.94422587 | F33: =(D33/$C$6)^$C$4 -> 0.87363335 | G33: =B33*E33*F33 -> 16.246597 | H33: =LN(G33) -> 2.7878835
A34: 2000 | B34: 19.76896 | C34: 3821.286 | D34: 180.9861 | E34: =(C34/$C$5)^$C$3 -> 0.94265404 | F34: =(D34/$C$6)^$C$4 -> 0.87737449 | G34: =B34*E34*F34 -> 16.350128 | H34: =LN(G34) -> 2.7942357
A35: 2001 | B35: 19.62363 | C35: 3879.288 | D35: 186.9203 | E35: =(C35/$C$5)^$C$3 -> 0.94910481 | F35: =(D35/$C$6)^$C$4 -> 0.88788019 | G35: =B35*E35*F35 -> 16.536663 | H35: =LN(G35) -> 2.8055799
A36: 2002 | B36: 19.45354 | C36: 3950.932 | D36: 195.4821 | E36: =(C36/$C$5)^$C$3 -> 0.95700034 | F36: =(D36/$C$6)^$C$4 -> 0.90267313 | G36: =B36*E36*F36 -> 16.805106 | H36: =LN(G36) -> 2.8216828
A37: 2003 | B37: 19.58451 | C37: 3998.835 | D37: 198.5784 | E37: =(C37/$C$5)^$C$3 -> 0.96223587 | F37: =(D37/$C$6)^$C$4 -> 0.90792204 | G37: =B37*E37*F37 -> 17.109716 | H37: =LN(G37) -> 2.8396465
A38: 2004 | B38: 19.2986 | C38: 4111.072 | D38: 210.5212 | E38: =(C38/$C$5)^$C$3 -> 0.97436983 | F38: =(D38/$C$6)^$C$4 -> 0.9276975 | G38: =B38*E38*F38 -> 17.444399 | H38: =LN(G38) -> 2.8590186
A39: 2005 | B39: 19.88375 | C39: 4059.441 | D39: 209.0953 | E39: =(C39/$C$5)^$C$3 -> 0.96881081 | F39: =(D39/$C$6)^$C$4 -> 0.92537428 | G39: =B39*E39*F39 -> 17.826032 | H39: =LN(G39) -> 2.8806599
... A58: 2024 | B58: 27.24521 | C58: 4353.748 | D58: 258.0114 | E58: =(C58/$C$5)^$C$3 -> 1 | F58: =(D58/$C$6)^$C$4 -> 1 | G58: =B58*E58*F58 -> 27.24521 | H58: =LN(G58) -> 3.3048777

Sheet Diffusion
A1: Technology S-curves (deck slide 7): logistic diffusion, share(t) = L / (1 + exp(-k (t - t0)))
A2: Share data: EPA Automotive Trends technology-share series (production-weighted), through the preliminary 2025 point, as used in the fit. L, k, t0 are the nonlinear least-squares estimates from 10_stats.py (scipy curve_fit; 95% CIs from a 300-draw residual bootstrap); they are the only typed inputs on this sheet. Everything else is live: the fitted curve, residuals, R-squared, 10-to-90% years, projections, and an independent Excel cross-check that re-estimates k and t0 by a linearized fit (SLOPE and INTERCEPT of ln(share / (L - share)) on year, valid where 0 < share < L).
A4: Technology | B4: Ceiling L | C4: L status | D4: k (NLS) | E4: 95% CI k | F4: midpoint t0 (NLS) | G4: 95% CI t0 | H4: 10% to 90% years = LN(81)/k | I4: R-squared (live) | J4: k, Excel logit cross-check | K4: t0, Excel logit cross-check | L4: latest share (live) | M4: projected 2030 | N4: projected 2035 | O4: projected 2040
A5: Turbo | B5: 0.478 | C5: estimated | D5: 0.287 | E5: 0.243 to 0.324 | F5: 2017.3 | G5: 2016.5 to 2018.5 | H5: =LN(81)/D5 -> 15.31167 | I5: =1-SUMSQ(D16:D45)/DEVSQ(B16:B45) -> 0.98880164 | J5: =SLOPE(E16:E45,A16:A45) -> 0.24909092 | K5: =-INTERCEPT(E16:E45,A16:A45)/J5 -> 2017.2223 | L5: =B45 -> 0.448 | M5: =B5/(1+EXP(-D5*(2030-F5))) -> 0.46583063 | N5: =B5/(1+EXP(-D5*(2035-F5))) -> 0.47504497 | O5: =B5/(1+EXP(-D5*(2040-F5))) -> 0.47729303
A6: GDI | B6: 0.535 | C6: estimated | D6: 0.612 | E6: 0.547 to 0.692 | F6: 2012.6 | G6: 2012.4 to 2012.8 | H6: =LN(81)/D6 -> 7.1804725 | I6: =1-SUMSQ(J16:J33)/DEVSQ(H16:H33) -> 0.99270687 | J6: =SLOPE(K16:K33,G16:G33) -> 0.45437303 | K6: =-INTERCEPT(K16:K33,G16:G33)/J6 -> 2012.7471 | L6: =H33 -> 0.52 | M6: =B6/(1+EXP(-D6*(2030-F6))) -> 0.53498731 | N6: =B6/(1+EXP(-D6*(2035-F6))) -> 0.5349994 | O6: =B6/(1+EXP(-D6*(2040-F6))) -> 0.53499997
A7: CVT | B7: 0.216 | C7: estimated | D7: 0.437 | E7: 0.346 to 0.546 | F7: 2011.5 | G7: 2010.9 to 2012.1 | H7: =LN(81)/D7 -> 10.055948 | I7: =1-SUMSQ(P16:P50)/DEVSQ(N16:N50) -> 0.97299125 | J7: =SLOPE(Q16:Q50,M16:M50) -> 0.30699425 | K7: =-INTERCEPT(Q16:Q50,M16:M50)/J7 -> 2011.608 | L7: =N50 -> 0.192 | M7: =B7/(1+EXP(-D7*(2030-F7))) -> 0.21593343 | N7: =B7/(1+EXP(-D7*(2035-F7))) -> 0.21599251 | O7: =B7/(1+EXP(-D7*(2040-F7))) -> 0.21599916
A8: Hybrid (HEV) | B8: 1 | C8: assumed (takeoff) | D8: 0.184 | E8: 0.126 to 0.203 | F8: 2036.2 | G8: 2034.5 to 2042.4 | H8: =LN(81)/D8 -> 23.882876 | I8: =1-SUMSQ(V16:V40)/DEVSQ(T16:T40) -> 0.82205316 | J8: =SLOPE(W16:W40,S16:S40) -> 0.15749534 | K8: =-INTERCEPT(W16:W40,S16:S40)/J8 -> 2038.3201 | L8: =T40 -> 0.14 | M8: =B8/(1+EXP(-D8*(2030-F8))) -> 0.24217351 | N8: =B8/(1+EXP(-D8*(2035-F8))) -> 0.44502317 | O8: =B8/(1+EXP(-D8*(2040-F8))) -> 0.66801038
A9: BEV | B9: 1 | C9: assumed (takeoff) | D9: 0.291 | E9: 0.229 to 0.398 | F9: 2032.3 | G9: 2029.7 to 2034.5 | H9: =LN(81)/D9 -> 15.1012 | I9: =1-SUMSQ(AB16:AB30)/DEVSQ(Z16:Z30) -> 0.90219117 | J9: =SLOPE(AC16:AC30,Y16:Y30) -> 0.34784091 | K9: =-INTERCEPT(AC16:AC30,Y16:Y30)/J9 -> 2030.8594 | L9: =Z30 -> 0.098 | M9: =B9/(1+EXP(-D9*(2030-F9))) -> 0.3386536 | N9: =B9/(1+EXP(-D9*(2035-F9))) -> 0.68690729 | O9: =B9/(1+EXP(-D9*(2040-F9))) -> 0.90384531
A11: Reading: the three completed curves (turbo, GDI, CVT) have data on both sides of the midpoint, so L is estimated. Hybrid and BEV are still on the ramp: a free fit cannot identify L, so it is fixed at 1 (takeoff assumed) and only k and t0 are estimated; their midpoints lie beyond the data. The logit cross-check weights points differently from nonlinear least squares (it up-weights the tails), so it lands near, not on, the NLS values.
A14: Turbo | G14: GDI | M14: CVT | S14: Hybrid (HEV) | Y14: BEV
A15: year | B15: share | C15: fitted | D15: residual | E15: logit ln(s/(L-s)) | G15: year | H15: share | I15: fitted | J15: residual | K15: logit ln(s/(L-s)) | M15: year | N15: share | O15: fitted | P15: residual | Q15: logit ln(s/(L-s)) | S15: year | T15: share | U15: fitted | V15: residual | W15: logit ln(s/(L-s)) | Y15: year | Z15: share | AA15: fitted | AB15: residual | AC15: logit ln(s/(L-s))
A16: 1996 | B16: 0.001 | C16: =$B$5/(1+EXP(-$D$5*(A16-$F$5))) -> 0.0010558008 | D16: =B16-C16 -> -5.5800769e-05 | E16: =IF(AND(B16>0,B16<$B$5),LN(B16/($B$5-B16)),"") -> -6.1675165 | G16: 2008 | H16: 0.023 | I16: =$B$6/(1+EXP(-$D$6*(G16-$F$6))) -> 0.030231942 | J16: =H16-I16 -> -0.0072319416 | K16: =IF(AND(H16>0,H16<$B$6),LN(H16/($B$6-H16)),"") -> -3.1028304 | M16: 1989 | N16: 0.001 | O16: =$B$7/(1+EXP(-$D$7*(M16-$F$7))) -> 1.1593911e-05 | P16: =N16-O16 -> 0.00098840609 | Q16: =IF(AND(N16>0,N16<$B$7),LN(N16/($B$7-N16)),"") -> -5.370638 | S16: 2001 | T16: 0.001 | U16: =$B$8/(1+EXP(-$D$8*(S16-$F$8))) -> 0.0015363627 | V16: =T16-U16 -> -0.00053636269 | W16: =IF(AND(T16>0,T16<$B$8),LN(T16/($B$8-T16)),"") -> -6.9067548 | Y16: 2011 | Z16: 0.001 | AA16: =$B$9/(1+EXP(-$D$9*(Y16-$F$9))) -> 0.0020287594 | AB16: =Z16-AA16 -> -0.0010287594 | AC16: =IF(AND(Z16>0,Z16<$B$9),LN(Z16/($B$9-Z16)),"") -> -6.9067548
A17: 1997 | B17: 0.004 | C17: =$B$5/(1+EXP(-$D$5*(A17-$F$5))) -> 0.0014057423 | D17: =B17-C17 -> 0.0025942577 | E17: =IF(AND(B17>0,B17<$B$5),LN(B17/($B$5-B17)),"") -> -4.774913 | G17: 2009 | H17: 0.042 | I17: =$B$6/(1+EXP(-$D$6*(G17-$F$6))) -> 0.05321297 | J17: =H17-I17 -> -0.01121297 | K17: =IF(AND(H17>0,H17<$B$6),LN(H17/($B$6-H17)),"") -> -2.4628396 | M17: 1990 | N17: 0 | O17: =$B$7/(1+EXP(-$D$7*(M17-$F$7))) -> 1.7947496e-05 | P17: =N17-O17 -> -1.7947496e-05 | Q17: =IF(AND(N17>0,N17<$B$7),LN(N17/($B$7-N17)),"") | S17: 2002 | T17: 0.001 | U17: =$B$8/(1+EXP(-$D$8*(S17-$F$8))) -> 0.0018461593 | V17: =T17-U17 -> -0.00084615927 | W17: =IF(AND(T17>0,T17<$B$8),LN(T17/($B$8-T17)),"") -> -6.9067548 | Y17: 2012 | Z17: 0.001 | AA17: =$B$9/(1+EXP(-$D$9*(Y17-$F$9))) -> 0.002712144 | AB17: =Z17-AA17 -> -0.001712144 | AC17: =IF(AND(Z17>0,Z17<$B$9),LN(Z17/($B$9-Z17)),"") -> -6.9067548
A18: 1998 | B18: 0.007 | C18: =$B$5/(1+EXP(-$D$5*(A18-$F$5))) -> 0.0018712158 | D18: =B18-C18 -> 0.0051287842 | E18: =IF(AND(B18>0,B18<$B$5),LN(B18/($B$5-B18)),"") -> -4.2089479 | G18: 2010 | H18: 0.083 | I18: =$B$6/(1+EXP(-$D$6*(G18-$F$6))) -> 0.090530096 | J18: =H18-I18 -> -0.0075300958 | K18: =IF(AND(H18>0,H18<$B$6),LN(H18/($B$6-H18)),"") -> -1.6948416 | M18: 1991 | N18: 0 | O18: =$B$7/(1+EXP(-$D$7*(M18-$F$7))) -> 2.7782465e-05 | P18: =N18-O18 -> -2.7782465e-05 | Q18: =IF(AND(N18>0,N18<$B$7),LN(N18/($B$7-N18)),"") | S18: 2003 | T18: 0.001 | U18: =$B$8/(1+EXP(-$D$8*(S18-$F$8))) -> 0.0022182853 | V18: =T18-U18 -> -0.0012182853 | W18: =IF(AND(T18>0,T18<$B$8),LN(T18/($B$8-T18)),"") -> -6.9067548 | Y18: 2013 | Z18: 0.003 | AA18: =$B$9/(1+EXP(-$D$9*(Y18-$F$9))) -> 0.0036248895 | AB18: =Z18-AA18 -> -0.00062488949 | AC18: =IF(AND(Z18>0,Z18<$B$9),LN(Z18/($B$9-Z18)),"") -> -5.8061385
A19: 1999 | B19: 0.013 | C19: =$B$5/(1+EXP(-$D$5*(A19-$F$5))) -> 0.0024900129 | D19: =B19-C19 -> 0.010509987 | E19: =IF(AND(B19>0,B19<$B$5),LN(B19/($B$5-B19)),"") -> -3.577088 | G19: 2011 | H19: 0.154 | I19: =$B$6/(1+EXP(-$D$6*(G19-$F$6))) -> 0.14608204 | J19: =H19-I19 -> 0.0079179558 | K19: =IF(AND(H19>0,H19<$B$6),LN(H19/($B$6-H19)),"") -> -0.90584677 | M19: 1992 | N19: 0 | O19: =$B$7/(1+EXP(-$D$7*(M19-$F$7))) -> 4.3005782e-05 | P19: =N19-O19 -> -4.3005782e-05 | Q19: =IF(AND(N19>0,N19<$B$7),LN(N19/($B$7-N19)),"") | S19: 2004 | T19: 0.003 | U19: =$B$8/(1+EXP(-$D$8*(S19-$F$8))) -> 0.0026652197 | V19: =T19-U19 -> 0.00033478028 | W19: =IF(AND(T19>0,T19<$B$8),LN(T19/($B$8-T19)),"") -> -5.8061385 | Y19: 2014 | Z19: 0.003 | AA19: =$B$9/(1+EXP(-$D$9*(Y19-$F$9))) -> 0.0048433188 | AB19: =Z19-AA19 -> -0.0018433188 | AC19: =IF(AND(Z19>0,Z19<$B$9),LN(Z19/($B$9-Z19)),"") -> -5.8061385
A20: 2000 | B20: 0.012 | C20: =$B$5/(1+EXP(-$D$5*(A20-$F$5))) -> 0.0033120181 | D20: =B20-C20 -> 0.0086879819 | E20: =IF(AND(B20>0,B20<$B$5),LN(B20/($B$5-B20)),"") -> -3.659279 | G20: 2012 | H20: 0.225 | I20: =$B$6/(1+EXP(-$D$6*(G20-$F$6))) -> 0.21893151 | J20: =H20-I20 -> 0.0060684914 | K20: =IF(AND(H20>0,H20<$B$6),LN(H20/($B$6-H20)),"") -> -0.3204719 | M20: 1993 | N20: 0 | O20: =$B$7/(1+EXP(-$D$7*(M20-$F$7))) -> 6.6568098e-05 | P20: =N20-O20 -> -6.6568098e-05 | Q20: =IF(AND(N20>0,N20<$B$7),LN(N20/($B$7-N20)),"") | S20: 2005 | T20: 0.008 | U20: =$B$8/(1+EXP(-$D$8*(S20-$F$8))) -> 0.0032019123 | V20: =T20-U20 -> 0.0047980877 | W20: =IF(AND(T20>0,T20<$B$8),LN(T20/($B$8-T20)),"") -> -4.8202816 | Y20: 2015 | Z20: 0.005 | AA20: =$B$9/(1+EXP(-$D$9*(Y20-$F$9))) -> 0.0064686383 | AB20: =Z20-AA20 -> -0.0014686383 | AC20: =IF(AND(Z20>0,Z20<$B$9),LN(Z20/($B$9-Z20)),"") -> -5.2933048
A21: 2001 | B21: 0.018 | C21: =$B$5/(1+EXP(-$D$5*(A21-$F$5))) -> 0.0044028718 | D21: =B21-C21 -> 0.013597128 | E21: =IF(AND(B21>0,B21<$B$5),LN(B21/($B$5-B21)),"") -> -3.2408547 | G21: 2013 | H21: 0.305 | I21: =$B$6/(1+EXP(-$D$6*(G21-$F$6))) -> 0.30007946 | J21: =H21-I21 -> 0.004920537 | K21: =IF(AND(H21>0,H21<$B$6),LN(H21/($B$6-H21)),"") -> 0.28223247 | M21: 1996 | N21: 0 | O21: =$B$7/(1+EXP(-$D$7*(M21-$F$7))) -> 0.0002467537 | P21: =N21-O21 -> -0.0002467537 | Q21: =IF(AND(N21>0,N21<$B$7),LN(N21/($B$7-N21)),"") | S21: 2006 | T21: 0.012 | U21: =$B$8/(1+EXP(-$D$8*(S21-$F$8))) -> 0.0038462614 | V21: =T21-U21 -> 0.0081537386 | W21: =IF(AND(T21>0,T21<$B$8),LN(T21/($B$8-T21)),"") -> -4.410776 | Y21: 2016 | Z21: 0.005 | AA21: =$B$9/(1+EXP(-$D$9*(Y21-$F$9))) -> 0.0086346496 | AB21: =Z21-AA21 -> -0.0036346496 | AC21: =IF(AND(Z21>0,Z21<$B$9),LN(Z21/($B$9-Z21)),"") -> -5.2933048
A22: 2002 | B22: 0.02 | C22: =$B$5/(1+EXP(-$D$5*(A22-$F$5))) -> 0.0058485849 | D22: =B22-C22 -> 0.014151415 | E22: =IF(AND(B22>0,B22<$B$5),LN(B22/($B$5-B22)),"") -> -3.1311369 | G22: 2014 | H22: 0.374 | I22: =$B$6/(1+EXP(-$D$6*(G22-$F$6))) -> 0.37556553 | J22: =H22-I22 -> -0.0015655324 | K22: =IF(AND(H22>0,H22<$B$6),LN(H22/($B$6-H22)),"") -> 0.84285143 | M22: 1997 | N22: 0 | O22: =$B$7/(1+EXP(-$D$7*(M22-$F$7))) -> 0.00038174955 | P22: =N22-O22 -> -0.00038174955 | Q22: =IF(AND(N22>0,N22<$B$7),LN(N22/($B$7-N22)),"") | S22: 2007 | T22: 0.019 | U22: =$B$8/(1+EXP(-$D$8*(S22-$F$8))) -> 0.0046196775 | V22: =T22-U22 -> 0.014380322 | W22: =IF(AND(T22>0,T22<$B$8),LN(T22/($B$8-T22)),"") -> -3.9441335 | Y22: 2017 | Z22: 0.006 | AA22: =$B$9/(1+EXP(-$D$9*(Y22-$F$9))) -> 0.011517538 | AB22: =Z22-AA22 -> -0.0055175378 | AC22: =IF(AND(Z22>0,Z22<$B$9),LN(Z22/($B$9-Z22)),"") -> -5.1099777
A23: 2003 | B23: 0.01 | C23: =$B$5/(1+EXP(-$D$5*(A23-$F$5))) -> 0.0077612282 | D23: =B23-C23 -> 0.0022387718 | E23: =IF(AND(B23>0,B23<$B$5),LN(B23/($B$5-B23)),"") -> -3.8458832 | G23: 2015 | H23: 0.419 | I23: =$B$6/(1+EXP(-$D$6*(G23-$F$6))) -> 0.43488808 | J23: =H23-I23 -> -0.015888084 | K23: =IF(AND(H23>0,H23<$B$6),LN(H23/($B$6-H23)),"") -> 1.2842807 | M23: 1998 | N23: 0 | O23: =$B$7/(1+EXP(-$D$7*(M23-$F$7))) -> 0.00059039784 | P23: =N23-O23 -> -0.00059039784 | Q23: =IF(AND(N23>0,N23<$B$7),LN(N23/($B$7-N23)),"") | S23: 2008 | T23: 0.022 | U23: =$B$8/(1+EXP(-$D$8*(S23-$F$8))) -> 0.005547748 | V23: =T23-U23 -> 0.016452252 | W23: =IF(AND(T23>0,T23<$B$8),LN(T23/($B$8-T23)),"") -> -3.7944672 | Y23: 2018 | Z23: 0.014 | AA23: =$B$9/(1+EXP(-$D$9*(Y23-$F$9))) -> 0.015348047 | AB23: =Z23-AA23 -> -0.001348047 | AC23: =IF(AND(Z23>0,Z23<$B$9),LN(Z23/($B$9-Z23)),"") -> -4.254599
A24: 2004 | B24: 0.021 | C24: =$B$5/(1+EXP(-$D$5*(A24-$F$5))) -> 0.010285731 | D24: =B24-C24 -> 0.010714269 | E24: =IF(AND(B24>0,B24<$B$5),LN(B24/($B$5-B24)),"") -> -3.080161 | G24: 2016 | H24: 0.48 | I24: =$B$6/(1+EXP(-$D$6*(G24-$F$6))) -> 0.4756273 | J24: =H24-I24 -> 0.0043727021 | K24: =IF(AND(H24>0,H24<$B$6),LN(H24/($B$6-H24)),"") -> 2.1664529 | M24: 1999 | N24: 0 | O24: =$B$7/(1+EXP(-$D$7*(M24-$F$7))) -> 0.00091260188 | P24: =N24-O24 -> -0.00091260188 | Q24: =IF(AND(N24>0,N24<$B$7),LN(N24/($B$7-N24)),"") | S24: 2009 | T24: 0.02 | U24: =$B$8/(1+EXP(-$D$8*(S24-$F$8))) -> 0.0066610157 | V24: =T24-U24 -> 0.013338984 | W24: =IF(AND(T24>0,T24<$B$8),LN(T24/($B$8-T24)),"") -> -3.8918203 | Y24: 2019 | Z24: 0.012 | AA24: =$B$9/(1+EXP(-$D$9*(Y24-$F$9))) -> 0.020426184 | AB24: =Z24-AA24 -> -0.0084261838 | AC24: =IF(AND(Z24>0,Z24<$B$9),LN(Z24/($B$9-Z24)),"") -> -4.410776
A25: 2005 | B25: 0.014 | C25: =$B$5/(1+EXP(-$D$5*(A25-$F$5))) -> 0.013607619 | D25: =B25-C25 -> 0.00039238117 | E25: =IF(AND(B25>0,B25<$B$5),LN(B25/($B$5-B25)),"") -> -3.5008272 | G25: 2017 | H25: 0.497 | I25: =$B$6/(1+EXP(-$D$6*(G25-$F$6))) -> 0.50108124 | J25: =H25-I25 -> -0.0040812403 | K25: =IF(AND(H25>0,H25<$B$6),LN(H25/($B$6-H25)),"") -> 2.5710039 | M25: 2000 | N25: 0 | O25: =$B$7/(1+EXP(-$D$7*(M25-$F$7))) -> 0.0014094951 | P25: =N25-O25 -> -0.0014094951 | Q25: =IF(AND(N25>0,N25<$B$7),LN(N25/($B$7-N25)),"") | S25: 2010 | T25: 0.038 | U25: =$B$8/(1+EXP(-$D$8*(S25-$F$8))) -> 0.0079958868 | V25: =T25-U25 -> 0.030004113 | W25: =IF(AND(T25>0,T25<$B$8),LN(T25/($B$8-T25)),"") -> -3.2314283 | Y25: 2020 | Z25: 0.018 | AA25: =$B$9/(1+EXP(-$D$9*(Y25-$F$9))) -> 0.027138192 | AB25: =Z25-AA25 -> -0.0091381923 | AC25: =IF(AND(Z25>0,Z25<$B$9),LN(Z25/($B$9-Z25)),"") -> -3.9992196
A26: 2006 | B26: 0.018 | C26: =$B$5/(1+EXP(-$D$5*(A26-$F$5))) -> 0.017961147 | D26: =B26-C26 -> 3.8852585e-05 | E26: =IF(AND(B26>0,B26<$B$5),LN(B26/($B$5-B26)),"") -> -3.2408547 | G26: 2018 | H26: 0.502 | I26: =$B$6/(1+EXP(-$D$6*(G26-$F$6))) -> 0.51605732 | J26: =H26-I26 -> -0.014057315 | K26: =IF(AND(H26>0,H26<$B$6),LN(H26/($B$6-H26)),"") -> 2.7220926 | M26: 2001 | N26: 0 | O26: =$B$7/(1+EXP(-$D$7*(M26-$F$7))) -> 0.0021742019 | P26: =N26-O26 -> -0.0021742019 | Q26: =IF(AND(N26>0,N26<$B$7),LN(N26/($B$7-N26)),"") | S26: 2011 | T26: 0.022 | U26: =$B$8/(1+EXP(-$D$8*(S26-$F$8))) -> 0.0095956825 | V26: =T26-U26 -> 0.012404317 | W26: =IF(AND(T26>0,T26<$B$8),LN(T26/($B$8-T26)),"") -> -3.7944672 | Y26: 2021 | Z26: 0.032 | AA26: =$B$9/(1+EXP(-$D$9*(Y26-$F$9))) -> 0.035974756 | AB26: =Z26-AA26 -> -0.0039747564 | AC26: =IF(AND(Z26>0,Z26<$B$9),LN(Z26/($B$9-Z26)),"") -> -3.4094962
A27: 2007 | B27: 0.025 | C27: =$B$5/(1+EXP(-$D$5*(A27-$F$5))) -> 0.023636622 | D27: =B27-C27 -> 0.0013633784 | E27: =IF(AND(B27>0,B27<$B$5),LN(B27/($B$5-B27)),"") -> -2.8970163 | G27: 2019 | H27: 0.529 | I27: =$B$6/(1+EXP(-$D$6*(G27-$F$6))) -> 0.52455882 | J27: =H27-I27 -> 0.0044411796 | K27: =IF(AND(H27>0,H27<$B$6),LN(H27/($B$6-H27)),"") -> 4.479229 | M27: 2002 | N27: 0.001 | O27: =$B$7/(1+EXP(-$D$7*(M27-$F$7))) -> 0.0033473207 | P27: =N27-O27 -> -0.0023473207 | Q27: =IF(AND(N27>0,N27<$B$7),LN(N27/($B$7-N27)),"") -> -5.370638 | S27: 2012 | T27: 0.03 | U27: =$B$8/(1+EXP(-$D$8*(S27-$F$8))) -> 0.011511847 | V27: =T27-U27 -> 0.018488153 | W27: =IF(AND(T27>0,T27<$B$8),LN(T27/($B$8-T27)),"") -> -3.4760987 | Y27: 2022 | Z27: 0.052 | AA27: =$B$9/(1+EXP(-$D$9*(Y27-$F$9))) -> 0.047547999 | AB27: =Z27-AA27 -> 0.0044520007 | AC27: =IF(AND(Z27>0,Z27<$B$9),LN(Z27/($B$9-Z27)),"") -> -2.9031108
... A30: 2010 | B30: 0.026 | C30: =$B$5/(1+EXP(-$D$5*(A30-$F$5))) -> 0.052376366 | D30: =B30-C30 -> -0.026376366 | E30: =IF(AND(B30>0,B30<$B$5),LN(B30/($B$5-B30)),"") -> -2.8555856 | G30: 2022 | H30: 0.523 | I30: =$B$6/(1+EXP(-$D$6*(G30-$F$6))) -> 0.53330735 | J30: =H30-I30 -> -0.010307346 | K30: =IF(AND(H30>0,H30<$B$6),LN(H30/($B$6-H30)),"") -> 3.7746748 | M30: 2005 | N30: 0.013 | O30: =$B$7/(1+EXP(-$D$7*(M30-$F$7))) -> 0.011917685 | P30: =N30-O30 -> 0.0010823152 | Q30: =IF(AND(N30>0,N30<$B$7),LN(N30/($B$7-N30)),"") -> -2.7482566 | S30: 2015 | T30: 0.024 | U30: =$B$8/(1+EXP(-$D$8*(S30-$F$8))) -> 0.019824754 | V30: =T30-U30 -> 0.0041752456 | W30: =IF(AND(T30>0,T30<$B$8),LN(T30/($B$8-T30)),"") -> -3.7054088 | Y30: 2025 | Z30: 0.098 | AA30: =$B$9/(1+EXP(-$D$9*(Y30-$F$9))) -> 0.10675733 | AB30: =Z30-AA30 -> -0.0087573277 | AC30: =IF(AND(Z30>0,Z30<$B$9),LN(Z30/($B$9-Z30)),"") -> -2.219647
